Workbook

Sheet Priority Summary
A1: TENU.WORLD — RESTE-À-FAIRE DASHBOARD
A2: Last reconciled: 2026-04-18 | Week 2-3 of build | Soft launch 11 May 2026
A4: BY PRIORITY
A5: Priority | B5: Open count | C5: Description
A6: P0 (Blocker) | B6: =COUNTIFS('Reste-à-Faire'!F:F,"P0",'Reste-à-Faire'!E:E,"<>Done",'Reste-à-Faire'!E:E,"<>Cancelled",'Reste-à-Faire'!E:E,"<>") -> 14 | C6: Must clear before soft launch 11 May 2026
A7: P1 (Launch) | B7: =COUNTIFS('Reste-à-Faire'!F:F,"P1",'Reste-à-Faire'!E:E,"<>Done",'Reste-à-Faire'!E:E,"<>Cancelled",'Reste-à-Faire'!E:E,"<>") -> 20 | C7: Required during Week 2-4 build window
A8: P2 (Post-launch) | B8: =COUNTIFS('Reste-à-Faire'!F:F,"P2",'Reste-à-Faire'!E:E,"<>Done",'Reste-à-Faire'!E:E,"<>Cancelled",'Reste-à-Faire'!E:E,"<>") -> 7 | C8: Can ship after first paying cohort
A10: BY DOMAIN
A11: Domain | B11: Total | C11: P0 | D11: P1 | E11: P2
A12: Agents | B12: =COUNTIF('Reste-à-Faire'!B:B,"Agents") -> 5 | C12: =COUNTIFS('Reste-à-Faire'!B:B,"Agents",'Reste-à-Faire'!F:F,"P0") -> 3 | D12: =COUNTIFS('Reste-à-Faire'!B:B,"Agents",'Reste-à-Faire'!F:F,"P1") -> 2 | E12: =COUNTIFS('Reste-à-Faire'!B:B,"Agents",'Reste-à-Faire'!F:F,"P2") -> 0
A13: Backend | B13: =COUNTIF('Reste-à-Faire'!B:B,"Backend") -> 9 | C13: =COUNTIFS('Reste-à-Faire'!B:B,"Backend",'Reste-à-Faire'!F:F,"P0") -> 8 | D13: =COUNTIFS('Reste-à-Faire'!B:B,"Backend",'Reste-à-Faire'!F:F,"P1") -> 1 | E13: =COUNTIFS('Reste-à-Faire'!B:B,"Backend",'Reste-à-Faire'!F:F,"P2") -> 0
A14: Brand | B14: =COUNTIF('Reste-à-Faire'!B:B,"Brand") -> 4 | C14: =COUNTIFS('Reste-à-Faire'!B:B,"Brand",'Reste-à-Faire'!F:F,"P0") -> 1 | D14: =COUNTIFS('Reste-à-Faire'!B:B,"Brand",'Reste-à-Faire'!F:F,"P1") -> 3 | E14: =COUNTIFS('Reste-à-Faire'!B:B,"Brand",'Reste-à-Faire'!F:F,"P2") -> 0
A15: Database | B15: =COUNTIF('Reste-à-Faire'!B:B,"Database") -> 2 | C15: =COUNTIFS('Reste-à-Faire'!B:B,"Database",'Reste-à-Faire'!F:F,"P0") -> 2 | D15: =COUNTIFS('Reste-à-Faire'!B:B,"Database",'Reste-à-Faire'!F:F,"P1") -> 0 | E15: =COUNTIFS('Reste-à-Faire'!B:B,"Database",'Reste-à-Faire'!F:F,"P2") -> 0
A16: Finance | B16: =COUNTIF('Reste-à-Faire'!B:B,"Finance") -> 2 | C16: =COUNTIFS('Reste-à-Faire'!B:B,"Finance",'Reste-à-Faire'!F:F,"P0") -> 0 | D16: =COUNTIFS('Reste-à-Faire'!B:B,"Finance",'Reste-à-Faire'!F:F,"P1") -> 1 | E16: =COUNTIFS('Reste-à-Faire'!B:B,"Finance",'Reste-à-Faire'!F:F,"P2") -> 1
A17: Frontend | B17: =COUNTIF('Reste-à-Faire'!B:B,"Frontend") -> 5 | C17: =COUNTIFS('Reste-à-Faire'!B:B,"Frontend",'Reste-à-Faire'!F:F,"P0") -> 2 | D17: =COUNTIFS('Reste-à-Faire'!B:B,"Frontend",'Reste-à-Faire'!F:F,"P1") -> 2 | E17: =COUNTIFS('Reste-à-Faire'!B:B,"Frontend",'Reste-à-Faire'!F:F,"P2") -> 1
A18: Governance | B18: =COUNTIF('Reste-à-Faire'!B:B,"Governance") -> 1 | C18: =COUNTIFS('Reste-à-Faire'!B:B,"Governance",'Reste-à-Faire'!F:F,"P0") -> 0 | D18: =COUNTIFS('Reste-à-Faire'!B:B,"Governance",'Reste-à-Faire'!F:F,"P1") -> 0 | E18: =COUNTIFS('Reste-à-Faire'!B:B,"Governance",'Reste-à-Faire'!F:F,"P2") -> 1
A19: Infrastructure | B19: =COUNTIF('Reste-à-Faire'!B:B,"Infrastructure") -> 10 | C19: =COUNTIFS('Reste-à-Faire'!B:B,"Infrastructure",'Reste-à-Faire'!F:F,"P0") -> 8 | D19: =COUNTIFS('Reste-à-Faire'!B:B,"Infrastructure",'Reste-à-Faire'!F:F,"P1") -> 2 | E19: =COUNTIFS('Reste-à-Faire'!B:B,"Infrastructure",'Reste-à-Faire'!F:F,"P2") -> 0
A20: Legal | B20: =COUNTIF('Reste-à-Faire'!B:B,"Legal") -> 12 | C20: =COUNTIFS('Reste-à-Faire'!B:B,"Legal",'Reste-à-Faire'!F:F,"P0") -> 11 | D20: =COUNTIFS('Reste-à-Faire'!B:B,"Legal",'Reste-à-Faire'!F:F,"P1") -> 1 | E20: =COUNTIFS('Reste-à-Faire'!B:B,"Legal",'Reste-à-Faire'!F:F,"P2") -> 0
A21: Marketing | B21: =COUNTIF('Reste-à-Faire'!B:B,"Marketing") -> 6 | C21: =COUNTIFS('Reste-à-Faire'!B:B,"Marketing",'Reste-à-Faire'!F:F,"P0") -> 0 | D21: =COUNTIFS('Reste-à-Faire'!B:B,"Marketing",'Reste-à-Faire'!F:F,"P1") -> 5 | E21: =COUNTIFS('Reste-à-Faire'!B:B,"Marketing",'Reste-à-Faire'!F:F,"P2") -> 1
A22: Mobile | B22: =COUNTIF('Reste-à-Faire'!B:B,"Mobile") -> 8 | C22: =COUNTIFS('Reste-à-Faire'!B:B,"Mobile",'Reste-à-Faire'!F:F,"P0") -> 0 | D22: =COUNTIFS('Reste-à-Faire'!B:B,"Mobile",'Reste-à-Faire'!F:F,"P1") -> 2 | E22: =COUNTIFS('Reste-à-Faire'!B:B,"Mobile",'Reste-à-Faire'!F:F,"P2") -> 6
A23: Paperclip | B23: =COUNTIF('Reste-à-Faire'!B:B,"Paperclip") -> 35 | C23: =COUNTIFS('Reste-à-Faire'!B:B,"Paperclip",'Reste-à-Faire'!F:F,"P0") -> 0 | D23: =COUNTIFS('Reste-à-Faire'!B:B,"Paperclip",'Reste-à-Faire'!F:F,"P1") -> 35 | E23: =COUNTIFS('Reste-à-Faire'!B:B,"Paperclip",'Reste-à-Faire'!F:F,"P2") -> 0
A24: Pipeline | B24: =COUNTIF('Reste-à-Faire'!B:B,"Pipeline") -> 4 | C24: =COUNTIFS('Reste-à-Faire'!B:B,"Pipeline",'Reste-à-Faire'!F:F,"P0") -> 3 | D24: =COUNTIFS('Reste-à-Faire'!B:B,"Pipeline",'Reste-à-Faire'!F:F,"P1") -> 1 | E24: =COUNTIFS('Reste-à-Faire'!B:B,"Pipeline",'Reste-à-Faire'!F:F,"P2") -> 0
A25: Pricing | B25: =COUNTIF('Reste-à-Faire'!B:B,"Pricing") -> 1 | C25: =COUNTIFS('Reste-à-Faire'!B:B,"Pricing",'Reste-à-Faire'!F:F,"P0") -> 1 | D25: =COUNTIFS('Reste-à-Faire'!B:B,"Pricing",'Reste-à-Faire'!F:F,"P1") -> 0 | E25: =COUNTIFS('Reste-à-Faire'!B:B,"Pricing",'Reste-à-Faire'!F:F,"P2") -> 0
A26: Product | B26: =COUNTIF('Reste-à-Faire'!B:B,"Product") -> 2 | C26: =COUNTIFS('Reste-à-Faire'!B:B,"Product",'Reste-à-Faire'!F:F,"P0") -> 0 | D26: =COUNTIFS('Reste-à-Faire'!B:B,"Product",'Reste-à-Faire'!F:F,"P1") -> 0 | E26: =COUNTIFS('Reste-à-Faire'!B:B,"Product",'Reste-à-Faire'!F:F,"P2") -> 2
A27: QA | B27: =COUNTIF('Reste-à-Faire'!B:B,"QA") -> 5 | C27: =COUNTIFS('Reste-à-Faire'!B:B,"QA",'Reste-à-Faire'!F:F,"P0") -> 2 | D27: =COUNTIFS('Reste-à-Faire'!B:B,"QA",'Reste-à-Faire'!F:F,"P1") -> 3 | E27: =COUNTIFS('Reste-à-Faire'!B:B,"QA",'Reste-à-Faire'!F:F,"P2") -> 0
A28: i18n | B28: =COUNTIF('Reste-à-Faire'!B:B,"i18n") -> 7 | C28: =COUNTIFS('Reste-à-Faire'!B:B,"i18n",'Reste-à-Faire'!F:F,"P0") -> 0 | D28: =COUNTIFS('Reste-à-Faire'!B:B,"i18n",'Reste-à-Faire'!F:F,"P1") -> 6 | E28: =COUNTIFS('Reste-à-Faire'!B:B,"i18n",'Reste-à-Faire'!F:F,"P2") -> 1
A29: TOTAL | B29: =SUM(B12:B28) -> 118 | C29: =SUM(C12:C28) -> 41 | D29: =SUM(D12:D28) -> 64 | E29: =SUM(E12:E28) -> 13
A31: BY OWNER
A32: Owner | B32: Total | C32: P0 | D32: P1 | E32: P2
A33: Claude Cowork | B33: =COUNTIF('Reste-à-Faire'!D:D,"Claude Cowork") -> 53 | C33: =COUNTIFS('Reste-à-Faire'!D:D,"Claude Cowork",'Reste-à-Faire'!F:F,"P0") -> 25 | D33: =COUNTIFS('Reste-à-Faire'!D:D,"Claude Cowork",'Reste-à-Faire'!F:F,"P1") -> 20 | E33: =COUNTIFS('Reste-à-Faire'!D:D,"Claude Cowork",'Reste-à-Faire'!F:F,"P2") -> 8
A34: Dr Mubashir | B34: =COUNTIF('Reste-à-Faire'!D:D,"Dr Mubashir") -> 30 | C34: =COUNTIFS('Reste-à-Faire'!D:D,"Dr Mubashir",'Reste-à-Faire'!F:F,"P0") -> 16 | D34: =COUNTIFS('Reste-à-Faire'!D:D,"Dr Mubashir",'Reste-à-Faire'!F:F,"P1") -> 9 | E34: =COUNTIFS('Reste-à-Faire'!D:D,"Dr Mubashir",'Reste-à-Faire'!F:F,"P2") -> 5
A35: (Paperclip legacy) | B35: =COUNTIF('Reste-à-Faire'!B:B,"Paperclip") -> 35 | C35: =COUNTIFS('Reste-à-Faire'!B:B,"Paperclip",'Reste-à-Faire'!F:F,"P0") -> 0 | D35: =COUNTIFS('Reste-à-Faire'!B:B,"Paperclip",'Reste-à-Faire'!F:F,"P1") -> 35 | E35: =COUNTIFS('Reste-à-Faire'!B:B,"Paperclip",'Reste-à-Faire'!F:F,"P2") -> 0
A37: BY STATUS
A38: Status | B38: Count
A39: Done | B39: =COUNTIF('Reste-à-Faire'!E:E,"Done") -> 52
A40: In Progress | B40: =COUNTIF('Reste-à-Faire'!E:E,"In Progress") -> 8
A41: To Do | B41: =COUNTIF('Reste-à-Faire'!E:E,"To Do") -> 33
A42: Cancelled | B42: =COUNTIF('Reste-à-Faire'!E:E,"Cancelled") -> 25
A45: CRITICAL PATH TO SOFT LAUNCH (11 May 2026)
A46: T-005 Brevo templates → T-020 Pipeline 1 payment→report → T-414 Dispute Sonnet → T-421 Consents
...

Sheet Governance Model
A1: TENU.WORLD — OPTION C GOVERNANCE MODEL
A3: Layer | B3: Actor | C3: Adapter | D3: Role | E3: Budget / Cost Control
A4: Strategic Review | B4: CEO Agent (Sonnet) | C4: claude_local | D4: Weekly strategic review: validates priorities, flags risks, reviews KPIs. Runs once per week on Monday. | E4: $15/month cap. ~$1-2 per review run.
A5: Technical Governance | B5: CTO Agent (Sonnet) | C5: claude_local | D5: Code review gatekeeper: reviews PRs, validates architecture decisions, approves scope changes. Runs on-demand when Dr Mubashir triggers. | E5: $20/month cap ($8.95 remaining). ~$1-3 per run.
A6: Execution | B6: Dr Mubashir + Claude Cowork | C6: N/A (this session) | D6: ALL code, config, deployment, testing, content writing. The human-AI pair does every deliverable. | E6: Included in Claude subscription.
A7: Monitoring | B7: Telegram Bot + LaunchAgent | C7: paperclip-monitor.py | D7: Automated alerts: failed runs, budget breaches, stalled work. Digest every 30 min. | E7: Free (runs locally).
A9: DECISION RULE
A10: CEO runs weekly. CTO runs only when you say so. Everything else is you + me.
A12: WHAT CHANGES FROM CURRENT SETUP
A13: Before | B13: After
A14: 10 agents, 8 on Ollama (all failing) | B14: 2 agents on Sonnet (governance only)
A15: gemma4:e4b doing dev tasks (0% success) | B15: Claude Cowork does all dev (100% success)
A16: No systematic tracking | B16: Excel reste-à-faire + Paperclip issues
A17: Ad hoc follow-up | B17: Weekly CEO review + on-demand CTO review

Sheet Reste-à-Faire
A1: ID | B1: Domain | C1: Task | D1: Owner | E1: Status | F1: Priority | G1: Deadline | H1: Dependency | I1: Deliverable | J1: Notes
A2: T-001 | B2: Infrastructure | C2: Set up Supabase project (create project, run 001_schema.sql migration) | D2: Dr Mubashir | E2: Done | F2: P0 | G2: 46129 | H2: None | I2: Supabase project URL + anon key in .env.local | J2: [Session 8 04/16] Migrations 001+002 both run in Supabase
A3: T-002 | B3: Infrastructure | C3: Create Cloudflare R2 bucket (tenu-photos-eu, EU region, private) | D3: Dr Mubashir | E3: Done | F3: P0 | G3: 46129 | H3: None | I3: R2 account ID + access keys in .env.local | J3: [Session 7] R2 bucket created, keys in .env.local
A4: T-003 | B4: Infrastructure | C4: Configure Stripe account (products, prices, 6 discount codes, webhook endpoint) | D4: Dr Mubashir | E4: Done | F4: P0 | G4: 46129 | H4: None | I4: Stripe API keys + price IDs in .env.local | J4: [Session 7-8] Stripe test keys configured, dynamic pricing (no fixed products), webhook endpoint set
A5: T-004 | B5: Infrastructure | C5: Deploy to Vercel (connect GitHub repo, set env vars, verify tenu.world DNS) | D5: Dr Mubashir | E5: Done | F5: P0 | G5: 46130 | H5: T-001, T-002, T-003 | I5: tenu.world live with Next.js app | J5: [Session 6] Vercel deployed, tenu.world live, DNS configured
A6: T-005 | B6: Infrastructure | C6: Configure Brevo (domain verification, 3 email templates: report EN, report FR, 14-day survey) | D6: Dr Mubashir | E6: In Progress | F6: P1 | G6: 46132 | H6: T-004 | I6: Brevo API key in .env.local + templates live | J6: DNS records on Namecheap | [2026-04-18] Brevo SMTP in Supabase Auth configured (#46). Domain verify + 3 templates still open.
A7: T-010 | B7: i18n | C7: Complete hi.json (Hindi) dictionary | D7: Claude Cowork | E7: To Do | F7: P1 | G7: 46134 | H7: None | I7: src/lib/i18n/dictionaries/hi.json | J7: Native speaker review needed
A8: T-011 | B8: i18n | C8: Complete ja.json (Japanese) dictionary | D8: Claude Cowork | E8: To Do | F8: P1 | G8: 46134 | H8: None | I8: src/lib/i18n/dictionaries/ja.json | J8: Native speaker review needed
A9: T-012 | B9: i18n | C9: Complete es.json (Spanish) dictionary | D9: Claude Cowork | E9: To Do | F9: P1 | G9: 46134 | H9: None | I9: src/lib/i18n/dictionaries/es.json
A10: T-013 | B10: i18n | C10: Complete it.json (Italian) dictionary | D10: Claude Cowork | E10: To Do | F10: P1 | G10: 46134 | H10: None | I10: src/lib/i18n/dictionaries/it.json
A11: T-014 | B11: i18n | C11: Complete uk.json (Ukrainian) dictionary | D11: Claude Cowork | E11: To Do | F11: P2 | G11: 46137 | H11: None | I11: src/lib/i18n/dictionaries/uk.json
A12: T-015 | B12: i18n | C12: Native speaker review: zh.json (Chinese) | D12: Dr Mubashir | E12: To Do | F12: P1 | G12: 46141 | H12: None | I12: Reviewed zh.json committed | J12: Find reviewer in Chinese student network
A13: T-016 | B13: i18n | C13: Native speaker review: ar.json (Arabic) | D13: Dr Mubashir | E13: To Do | F13: P1 | G13: 46141 | H13: None | I13: Reviewed ar.json committed | J13: Find reviewer via ISOC or mosque network
A14: T-020 | B14: Pipeline | C14: Build Pipeline 1: Stripe webhook → Supabase user fetch → R2 photo fetch → Claude Haiku scan → PDF generation → R2 upload → Brevo email | D14: Claude Cowork | E14: In Progress | F14: P0 | G14: 46135 | H14: T-001, T-002, T-003, T-005 | I14: src/app/api/webhooks/stripe/route.ts (extended) | J14: This is the core revenue path | [2026-04-18] Risk-scan v2 on /api/ai/scan live (#22, #33). PDF gen + R2 upload + Brevo send still pending (#25).
A15: T-021 | B15: Pipeline | C15: Build Pipeline 2: Dispute add-on → Claude Sonnet letter → PDF append → R2 upload → Brevo email | D15: Claude Cowork | E15: In Progress | F15: P0 | G15: 46137 | H15: T-020 | I15: src/app/api/ai/dispute/route.ts (extended) | J15: [Sync 04/15 15:54] Paperclip: done | [2026-04-18] Dispute v2 spec shipped, /api/ai/dispute scaffold in place (#30). Sonnet handler still being finalised.
A16: T-022 | B16: Pipeline | C16: Build Pipeline 3: Supabase scheduled function → 14-day Brevo outcome survey → Supabase update | D16: Claude Cowork | E16: To Do | F16: P1 | G16: 46141 | H16: T-020, T-005 | I16: Supabase Edge Function or cron | J16: Outcome data feeds Year 1 metrics
A17: T-030 | B17: Legal | C17: Implement R2 signed URLs (no public photo access, 1-hour expiry) | D17: Claude Cowork | E17: Done | F17: P0 | G17: 46133 | H17: T-002 | I17: src/lib/storage/r2-upload.ts updated | J17: Critical for GDPR compliance | [2026-04-17] R2 signed URLs + evidence chain (sha256+EXIF) live on 0240bec (#23).
A18: T-031 | B18: Legal | C18: Implement 30-day photo deletion (Supabase cron + R2 delete) | D18: Claude Cowork | E18: To Do | F18: P0 | G18: 46135 | H18: T-001, T-002 | I18: Supabase Edge Function + R2 lifecycle | J18: GDPR data retention requirement
A19: T-032 | B19: Legal | C19: Create privacy policy page (/privacy) — FR + EN | D19: Claude Cowork | E19: Done | F19: P0 | G19: 46133 | H19: None | I19: src/app/privacy/page.tsx | J19: [Sync 04/17 12:18] Paperclip: done | [2026-04-17] /legal/privacy live FR+EN with DRAFT banner (#17).
A20: T-033 | B20: Legal | C20: Create terms of service page (/terms) — FR + EN | D20: Claude Cowork | E20: Done | F20: P0 | G20: 46133 | H20: None | I20: src/app/terms/page.tsx | J20: [Sync 04/17 12:18] Paperclip: done | [2026-04-17] /legal/terms live FR+EN with DRAFT banner (#17).
A21: T-034 | B21: Legal | C21: Commission FR avocat opinion (droit locatif, €500-1000) | D21: Dr Mubashir | E21: To Do | F21: P0 | G21: 46137 | H21: None | I21: Written legal opinion PDF | J21: Barreau de Paris or HEC network
A22: T-035 | B22: Legal | C22: Commission UK solicitor opinion (Legal Services Act 2007, £400-800) | D22: Dr Mubashir | E22: Cancelled | F22: P0 | G22: 46137 | H22: None | I22: Written legal opinion PDF | J22: Law Society directory | [2026-04-17] UK disabled at launch per pricing lock. Revisit after first FR cohort outcome data.
A23: T-036 | B23: Legal | C23: Add 'not legal advice' checkbox before report delivery | D23: Claude Cowork | E23: In Progress | F23: P1 | G23: 46135 | H23: T-020 | I23: UI checkbox + Supabase consent log | J23: Legal requirement per C1 risk | [2026-04-18] Consent touchpoints scoped (#29). Blocked by #47 Google OAuth External + #48 Magic Link template.
... A35: T-061 | B35: Marketing | C35: Post in Chinese student community (Facebook/WeChat) — demand validation | D35: Dr Mubashir | E35: To Do | F35: P1 | G35: 46134 | H35: T-060 | I35: 20+ signups in 48h = green light | J35: Use ZH copy from GTM plan
A36: T-062 | B36: Marketing | C36: Post in Reddit r/france (LOCATAIRE25 code) | D36: Dr Mubashir | E36: To Do | F36: P1 | G36: 46136 | H36: T-060 | I36: Signup count tracked
A37: T-063 | B37: Marketing | C37: Contact 3 UK ISOC housing officers (UMMAH25 code) | D37: Dr Mubashir | E37: To Do | F37: P2 | G37: 46141 | H37: T-060 | I37: 3 emails sent, responses tracked | J37: UCL, King's, Manchester
A38: T-064 | B38: Marketing | C38: Draft launch announcement for all 5 target communities | D38: Claude Cowork | E38: To Do | F38: P1 | G38: 46139 | H38: None | I38: 5 posts in ZH, AR, UR, EN, FR | J38: Community-specific messaging
A39: T-070 | B39: Finance | C39: Set up Global Apex bank tracking for Tenu expenses | D39: Dr Mubashir | E39: To Do | F39: P1 | G39: 46134 | H39: None | I39: Expense ledger (Excel or accounting tool) | J39: Separate cost center for Tenu
A40: T-071 | B40: Finance | C40: First monthly financial report (costs vs. projections) | D40: Dr Mubashir | E40: To Do | F40: P2 | G40: 46157 | H40: T-070 | I40: Financial report PDF/XLSX | J40: Compare to 04-Financial projections
A41: T-072 | B41: Governance | C41: Sign Make.com EU DPA (if any Make.com usage remains) | D41: Dr Mubashir | E41: Cancelled | F41: P2 | G41: 46141 | H41: None | I41: Signed DPA on file | J41: May not be needed if pipeline is all in-code | [2026-04-15] Pipeline moved fully in-code (Next.js API routes). No Make.com usage remains.
A42: T-080 | B42: Agents | C42: Reconfigure Paperclip: pause all Ollama agents, keep CEO + CTO active | D42: Dr Mubashir | E42: Done | F42: P0 | G42: 46127 | H42: None | I42: SQL executed, agents reconfigured | J42: SQL provided in this workbook | [2026-04-17] Option 2 executed (#18). All 10 agents paused, 14 issues closed. Dashboard-only mode.
A43: T-081 | B43: Agents | C43: Create CEO weekly review issue (Monday cadence) | D43: Dr Mubashir | E43: Cancelled | F43: P1 | G43: 46129 | H43: T-080 | I43: Recurring Paperclip issue | J43: CEO reviews priorities, flags risks | [2026-04-17] CEO weekly review retired with the agent fleet. Governance runs off the dashboard + Claude Cowork session cadence.
A44: T-082 | B44: Agents | C44: Set up Telegram bot for monitoring (BotFather → token + chat_id) | D44: Dr Mubashir | E44: In Progress | F44: P0 | G44: 46128 | H44: None | I44: ~/.paperclip-monitor.env populated | J44: Then: launchctl load the plist | [2026-04-17] Telegram push channel scoped (#32). Token + chat_id procurement open.
A45: T-083 | B45: Agents | C45: Activate LaunchAgent for paperclip-monitor | D45: Dr Mubashir | E45: Done | F45: P0 | G45: 46128 | H45: T-082 | I45: Monitor running every 5 min | J45: launchctl load ~/Library/LaunchAgents/com.globalapex.paperclip-monitor.plist | [2026-04-17] governance-sync LaunchAgent running every 30 min.
A46: T-084 | B46: Paperclip | C46: Hire your first engineer and create a hiring plan | D46: Head of HR | E46: Cancelled | F46: P1 | J46: [Auto-added from Paperclip 04/15] | [2026-04-17] Paperclip agent fleet retired (#18). Dashboard-only mode — this auto-generated entry is obsolete.
A47: T-086 | B47: Paperclip | C47: Set up technical foundation and development environment | D47: CTO | E47: Cancelled | F47: P1 | J47: [Auto-added from Paperclip 04/15] | [2026-04-17] Paperclip agent fleet retired (#18). Dashboard-only mode — this auto-generated entry is obsolete.
A48: T-089 | B48: Paperclip | C48: Define and build the first MVP app or AI agent | D48: CTO | E48: Cancelled | F48: P1 | J48: [Auto-added from Paperclip 04/15] | [2026-04-17] Paperclip agent fleet retired (#18). Dashboard-only mode — this auto-generated entry is obsolete.
A49: T-093 | B49: Paperclip | C49: CTO: Reactivate and deliver Week 2-4 technical roadmap for Tenu.World | D49: CTO | E49: Cancelled | F49: P1 | J49: [Auto-added from Paperclip 04/15] | [2026-04-17] Paperclip agent fleet retired (#18). Dashboard-only mode — this auto-generated entry is obsolete.
A50: T-098 | B50: Paperclip | C50: [Marketing] Week 4 launch plan: community outreach across 5 target segments | D50: Head of Marketing | E50: Cancelled | F50: P1 | J50: [Auto-added from Paperclip 04/15] | [2026-04-17] Paperclip agent fleet retired (#18). Dashboard-only mode — this auto-generated entry is obsolete.
A51: T-104 | B51: Paperclip | C51: [Finance] Weekly KPI dashboard and first monthly board financial report | D51: Head of Finance | E51: Cancelled | F51: P1 | J51: [Auto-added from Paperclip 04/15] | [2026-04-17] Paperclip agent fleet retired (#18). Dashboard-only mode — this auto-generated entry is obsolete.
...

Sheet Weekly Cadence
A1: Day | B1: Time | C1: Activity | D1: Who | E1: Input | F1: Output | G1: Duration
A2: Monday | B2: 09:00 | C2: CEO Agent weekly review run | D2: CEO Agent (auto) | E2: All open issues + status from Paperclip | F2: Strategic priority list + risk flags on Telegram | G2: ~5 min run
A3: Monday | B3: 09:30 | C3: Dr Mubashir reviews CEO output + updates reste-à-faire | D3: Dr Mubashir | E3: CEO review + this Excel | F3: Updated task statuses, new tasks if needed | G3: 15 min
A4: Mon-Thu | B4: Working hours | C4: Execution: Claude Cowork sessions on P0/P1 tasks | D4: Dr Mubashir + Claude | E4: Reste-à-faire priority order | F4: Code commits, configs, content | G4: As available
A5: Wednesday | B5: On demand | C5: CTO review run (if architecture decision needed) | D5: Dr Mubashir triggers | E5: Specific question or PR to review | F5: Technical recommendation on Telegram | G5: ~3 min run
A6: Friday | B6: 17:00 | C6: Weekly reste-à-faire update + git push | D6: Dr Mubashir + Claude | E6: This Excel + git status | F6: Updated Excel, clean git history | G6: 20 min
A7: Friday | B7: 17:30 | C7: Telegram digest: week summary (automated) | D7: Monitor script | E7: Paperclip DB state | F7: Agent run stats + issue counts | G7: Auto
A8: End of month | B8: Any | C8: Monthly financial review vs. projections | D8: Dr Mubashir | E8: Expenses + 04-Financial projections | F8: Variance report | G8: 1 hour

Sheet SQL Commands
A1: PAPERCLIP RECONFIGURATION SQL — Run these in order
A3: Step | B3: SQL Command
A4: 1. Cancel all queued wakeups | B4: UPDATE agent_wakeup_requests SET status = 'cancelled' WHERE status = 'queued';
A5: 2. Pause all Ollama agents | B5: UPDATE agents SET paused_at = NOW(), pause_reason = 'option_c_governance_only' WHERE adapter_type = 'codex_local';
A6: 3. Keep CEO + CTO active | B6: UPDATE agents SET paused_at = NULL, pause_reason = NULL WHERE adapter_type = 'claude_local';
A7: 4. Reset CTO budget (fresh start) | B7: UPDATE agents SET spent_monthly_cents = 0 WHERE name = 'CTO';
A8: 5. Close stale CTO issues | B8: UPDATE issues SET status = 'done' WHERE assignee_agent_id = (SELECT id FROM agents WHERE name = 'CTO') AND status IN ('backlog') AND title LIKE '%Hire%';
A9: 6. Close stale CTO directive | B9: UPDATE issues SET status = 'done' WHERE assignee_agent_id = (SELECT id FROM agents WHERE name = 'CTO') AND title LIKE '%OPERATING DIRECTIVE%';
A10: 7. Archive unassigned backlog | B10: UPDATE issues SET status = 'done' WHERE assignee_agent_id IS NULL AND status = 'backlog';
A12: VERIFICATION QUERY
A13: Check final state | B13: SELECT name, status, adapter_type, paused_at IS NOT NULL as paused, budget_monthly_cents, spent_monthly_cents FROM agents ORDER BY name;
A15: COMBINED ONE-LINER (copy-paste into Terminal)
A16: Full reconfiguration | B16: PGPASSWORD=paperclip /opt/homebrew/Cellar/libpq/18.3/bin/psql -h localhost -p 54329 -U paperclip -d paperclip -c " UPDATE agent_wakeup_requests SET status = 'cancelled' WHERE status = 'queued'; UPDATE agents SET paused_at = NOW(), pause_reason = 'option_c_governance_only' WHERE adapter_type = 'codex_local'; UPDATE agents SET paused_at = NULL, pause_reason = NULL WHERE adapter_type = 'claude_local'; UPDATE agents SET spent_monthly_cents = 0 WHERE name = 'CTO'; UPDATE issues SET status = 'done' WHERE assignee_agent_id = (SELECT id FROM agents WHERE name = 'CTO') AND status = 'backlog'; UPDATE issues SET status = 'done' WHERE assignee_agent_id IS NULL AND status = 'backlog'; SELECT name, status, adapter_type, CASE WHEN paused_at IS NOT NULL THEN 'PAUSED' ELSE 'ACTIVE' END as state, budget_monthly_cents/100 as budget_usd, spent_monthly_cents/100 as spent_usd FROM agents ORDER BY name; "

Sheet Paperclip Status
A1: PAPERCLIP STATUS — RETIRED 2026-04-17 (dashboard-only)
A2: Issue #18 closed: all 10 agents paused, 14 issues closed. governance-sync LaunchAgent runs every 30 min.
A3: Execution runs through Claude Cowork sessions; no agent fleet.
A5: Agent | B5: Adapter | C5: Model | D5: State | E5: Budget | F5: Spent | G5: Retirement note
A6: CEO | B6: codex_local | C6: gpt-4o-mini | D6: PAUSED | E6: $15 | F6: $4.06 | G6: Chat-only; never executed tool calls.
A7: CTO | B7: codex_local | C7: gpt-4o-mini | D7: PAUSED | E7: $20 | F7: $13.78 | G7: Chat-only; never executed tool calls.
A8: Head of Finance | B8: codex_local | C8: gemma4:e4b | D8: PAUSED | E8: $5 | F8: $0.00 | G8: Ollama adapter failed (0% success).
A9: Head of Governance | B9: codex_local | C9: gemma4:e4b | D9: PAUSED | E9: $5 | F9: $0.00 | G9: Ollama adapter failed (0% success).
A10: Head of HR | B10: codex_local | C10: gemma4:e4b | D10: PAUSED | E10: $5 | F10: $0.00 | G10: Ollama adapter failed (0% success).
A11: Head of Marketing | B11: codex_local | C11: gemma4:e4b | D11: PAUSED | E11: $5 | F11: $0.00 | G11: Ollama adapter failed (0% success).
A12: Head of Product | B12: codex_local | C12: gemma4:e4b | D12: PAUSED | E12: $5 | F12: $0.00 | G12: Ollama adapter failed (0% success).
A13: Senior Android Developer | B13: codex_local | C13: gemma4:e4b | D13: PAUSED | E13: $5 | F13: $0.00 | G13: Error state before retirement.
A14: Senior Web Developer | B14: codex_local | C14: gemma4:e4b | D14: PAUSED | E14: $5 | F14: $0.00 | G14: Ollama adapter failed (0% success).
A15: Senior iOS Developer | B15: codex_local | C15: gemma4:e4b | D15: PAUSED | E15: $5 | F15: $0.00 | G15: Error state before retirement.
A18: ISSUE SUMMARY (final, frozen 2026-04-17)
A19: done | B19: 42
A20: closed at retirement | B20: 14
A21: obsolete (T-084..T-316) | B21: 22
A23: REPLACEMENT
A24: Execution: Claude Cowork session cadence (see Weekly Cadence tab).
A25: Monitoring: governance-sync LaunchAgent every 30 min + Telegram digest (T-424 in progress).

Sheet Run History
A1: RUN HISTORY (Last 24h) — 2026-04-17 19:19
A3: Agent | B3: Status | C3: Duration | D3: Error | E3: Started | F3: Finished
A4: CEO | B4: succeeded | C4: 0m | E4: 2026-04-17 12:12:52 | F4: 2026-04-17 12:13:12
A5: CEO | B5: succeeded | C5: 0m | E5: 2026-04-17 12:07:22 | F5: 2026-04-17 12:07:30
A6: CEO | B6: succeeded | C6: 0m | E6: 2026-04-17 12:01:52 | F6: 2026-04-17 12:02:05
A7: CEO | B7: succeeded | C7: 0m | E7: 2026-04-17 11:56:22 | F7: 2026-04-17 11:56:37
A8: CEO | B8: succeeded | C8: 0m | E8: 2026-04-17 11:50:52 | F8: 2026-04-17 11:51:19
A9: CEO | B9: succeeded | C9: 0m | E9: 2026-04-17 11:45:22 | F9: 2026-04-17 11:45:29
A10: CEO | B10: succeeded | C10: 0m | E10: 2026-04-17 11:39:52 | F10: 2026-04-17 11:40:04
A11: CEO | B11: succeeded | C11: 0m | E11: 2026-04-17 11:34:22 | F11: 2026-04-17 11:34:41
A12: CEO | B12: succeeded | C12: 0m | E12: 2026-04-17 11:28:52 | F12: 2026-04-17 11:29:02
A13: CEO | B13: succeeded | C13: 0m | E13: 2026-04-17 11:23:22 | F13: 2026-04-17 11:23:28
A14: CEO | B14: succeeded | C14: 0m | E14: 2026-04-17 11:17:52 | F14: 2026-04-17 11:18:03
A15: CEO | B15: succeeded | C15: 0m | E15: 2026-04-17 11:12:14 | F15: 2026-04-17 11:12:43
... A37: CEO | B37: succeeded | C37: 8m | E37: 2026-04-17 09:23:27 | F37: 2026-04-17 09:31:27
A38: CEO | B38: timed_out | C38: 17m | D38: Timed out after 900s | E38: 2026-04-17 08:49:10 | F38: 2026-04-17 09:06:32
A39: CEO | B39: timed_out | C39: 16m | D39: Timed out after 900s | E39: 2026-04-17 08:16:50 | F39: 2026-04-17 08:33:02
A40: CEO | B40: succeeded | C40: 0m | E40: 2026-04-17 08:11:20 | F40: 2026-04-17 08:11:28
A41: CEO | B41: succeeded | C41: 0m | E41: 2026-04-17 08:05:50 | F41: 2026-04-17 08:06:12
A42: CEO | B42: succeeded | C42: 0m | E42: 2026-04-17 07:59:50 | F42: 2026-04-17 08:00:20
A43: CEO | B43: succeeded | C43: 0m | E43: 2026-04-17 07:54:20 | F43: 2026-04-17 07:54:45
A44: CEO | B44: timed_out | C44: 20m | D44: Timed out after 900s | E44: 2026-04-17 07:33:28 | F44: 2026-04-17 07:54:20
A45: CEO | B45: timed_out | C45: 16m | D45: Timed out after 900s | E45: 2026-04-17 07:16:37 | F45: 2026-04-17 07:33:28
A46: CEO | B46: timed_out | C46: 17m | D46: Timed out after 900s | E46: 2026-04-17 06:58:44 | F46: 2026-04-17 07:16:37
A47: CEO | B47: timed_out | C47: 28m | D47: Timed out after 900s | E47: 2026-04-17 06:30:30 | F47: 2026-04-17 06:58:44
A48: CEO | B48: timed_out | C48: 16m | D48: Timed out after 900s | E48: 2026-04-17 06:13:51 | F48: 2026-04-17 06:30:30
A49: CEO | B49: timed_out | C49: 17m | D49: Timed out after 900s | E49: 2026-04-17 05:40:44 | F49: 2026-04-17 05:57:55
A50: CEO | B50: timed_out | C50: 15m | D50: Timed out after 900s | E50: 2026-04-17 05:13:44 | F50: 2026-04-17 05:28:51
A51: CEO | B51: timed_out | C51: 30m | D51: Timed out after 900s | E51: 2026-04-17 04:26:04 | F51: 2026-04-17 04:56:33
A52: CEO | B52: timed_out | C52: 16m | D52: Timed out after 900s | E52: 2026-04-17 03:53:51 | F52: 2026-04-17 04:10:45
A53: CEO | B53: timed_out | C53: 15m | D53: Timed out after 900s | E53: 2026-04-17 03:38:43 | F53: 2026-04-17 03:53:51
A54: CEO | B54: timed_out | C54: 19m | D54: Timed out after 900s | E54: 2026-04-17 03:11:18 | F54: 2026-04-17 03:30:37
A55: CEO | B55: timed_out | C55: 16m | D55: Timed out after 900s | E55: 2026-04-17 02:37:43 | F55: 2026-04-17 02:54:24
... A68: CEO | B68: timed_out | C68: 15m | D68: Timed out after 900s | E68: 2026-04-16 19:47:03 | F68: 2026-04-16 20:02:06
A69: CEO | B69: succeeded | C69: 0m | E69: 2026-04-16 19:30:43 | F69: 2026-04-16 19:30:51
